url 2 1
url 2 10
XIO:  fatal IO error 11 (Resource temporarily unavailable) on X server "localhost:10.0"
      after 0 requests (0 known processed) with 0 events remaining.
url 20 10
Traceback (most recent call last):
  File "recall_precision.py", line 101, in <module>
    plt.scatter(group_record.values(), group_record.keys(), marker='x', label=f'FLINNG' )
  File "/usr/lib/python3/dist-packages/matplotlib/pyplot.py", line 3364, in scatter
    ax = gca()
  File "/usr/lib/python3/dist-packages/matplotlib/pyplot.py", line 962, in gca
    return gcf().gca(**kwargs)
  File "/usr/lib/python3/dist-packages/matplotlib/pyplot.py", line 592, in gcf
    return figure()
  File "/usr/lib/python3/dist-packages/matplotlib/pyplot.py", line 539, in figure
    **kwargs)
  File "/usr/lib/python3/dist-packages/matplotlib/backend_bases.py", line 171, in new_figure_manager
    return cls.new_figure_manager_given_figure(num, fig)
  File "/usr/lib/python3/dist-packages/matplotlib/backends/backend_tkagg.py", line 1049, in new_figure_manager_given_figure
    window = Tk.Tk(className="matplotlib")
  File "/usr/lib/python3.6/tkinter/__init__.py", line 2023, in __init__
    self.tk = _tkinter.create(screenName, baseName, className, interactive, wantobjects, useTk, sync, use)
_tkinter.TclError: couldn't connect to display "localhost:10.0"
url 200 1
Traceback (most recent call last):
  File "recall_precision.py", line 101, in <module>
    plt.scatter(group_record.values(), group_record.keys(), marker='x', label=f'FLINNG' )
  File "/usr/lib/python3/dist-packages/matplotlib/pyplot.py", line 3364, in scatter
    ax = gca()
  File "/usr/lib/python3/dist-packages/matplotlib/pyplot.py", line 962, in gca
    return gcf().gca(**kwargs)
  File "/usr/lib/python3/dist-packages/matplotlib/pyplot.py", line 592, in gcf
    return figure()
  File "/usr/lib/python3/dist-packages/matplotlib/pyplot.py", line 539, in figure
    **kwargs)
  File "/usr/lib/python3/dist-packages/matplotlib/backend_bases.py", line 171, in new_figure_manager
    return cls.new_figure_manager_given_figure(num, fig)
  File "/usr/lib/python3/dist-packages/matplotlib/backends/backend_tkagg.py", line 1049, in new_figure_manager_given_figure
    window = Tk.Tk(className="matplotlib")
  File "/usr/lib/python3.6/tkinter/__init__.py", line 2023, in __init__
    self.tk = _tkinter.create(screenName, baseName, className, interactive, wantobjects, useTk, sync, use)
_tkinter.TclError: couldn't connect to display "localhost:10.0"
url 200 10
Traceback (most recent call last):
  File "recall_precision.py", line 101, in <module>
    plt.scatter(group_record.values(), group_record.keys(), marker='x', label=f'FLINNG' )
  File "/usr/lib/python3/dist-packages/matplotlib/pyplot.py", line 3364, in scatter
    ax = gca()
  File "/usr/lib/python3/dist-packages/matplotlib/pyplot.py", line 962, in gca
    return gcf().gca(**kwargs)
  File "/usr/lib/python3/dist-packages/matplotlib/pyplot.py", line 592, in gcf
    return figure()
  File "/usr/lib/python3/dist-packages/matplotlib/pyplot.py", line 539, in figure
    **kwargs)
  File "/usr/lib/python3/dist-packages/matplotlib/backend_bases.py", line 171, in new_figure_manager
    return cls.new_figure_manager_given_figure(num, fig)
  File "/usr/lib/python3/dist-packages/matplotlib/backends/backend_tkagg.py", line 1049, in new_figure_manager_given_figure
    window = Tk.Tk(className="matplotlib")
  File "/usr/lib/python3.6/tkinter/__init__.py", line 2023, in __init__
    self.tk = _tkinter.create(screenName, baseName, className, interactive, wantobjects, useTk, sync, use)
_tkinter.TclError: couldn't connect to display "localhost:10.0"
url R1@1
Traceback (most recent call last):
  File "recall_time.py", line 47, in <module>
    plt.scatter([y for (x,y, z) in group_record if y > lower_bound], [math.log10(10000 / x * 1000) for (x,y, z) in group_record if y > lower_bound], marker='x', label=f'FLINNG' )
  File "/usr/lib/python3/dist-packages/matplotlib/pyplot.py", line 3364, in scatter
    ax = gca()
  File "/usr/lib/python3/dist-packages/matplotlib/pyplot.py", line 962, in gca
    return gcf().gca(**kwargs)
  File "/usr/lib/python3/dist-packages/matplotlib/pyplot.py", line 592, in gcf
    return figure()
  File "/usr/lib/python3/dist-packages/matplotlib/pyplot.py", line 539, in figure
    **kwargs)
  File "/usr/lib/python3/dist-packages/matplotlib/backend_bases.py", line 171, in new_figure_manager
    return cls.new_figure_manager_given_figure(num, fig)
  File "/usr/lib/python3/dist-packages/matplotlib/backends/backend_tkagg.py", line 1049, in new_figure_manager_given_figure
    window = Tk.Tk(className="matplotlib")
  File "/usr/lib/python3.6/tkinter/__init__.py", line 2023, in __init__
    self.tk = _tkinter.create(screenName, baseName, className, interactive, wantobjects, useTk, sync, use)
_tkinter.TclError: couldn't connect to display "localhost:10.0"
url R1@10
Traceback (most recent call last):
  File "recall_time.py", line 47, in <module>
    plt.scatter([y for (x,y, z) in group_record if y > lower_bound], [math.log10(10000 / x * 1000) for (x,y, z) in group_record if y > lower_bound], marker='x', label=f'FLINNG' )
  File "/usr/lib/python3/dist-packages/matplotlib/pyplot.py", line 3364, in scatter
    ax = gca()
  File "/usr/lib/python3/dist-packages/matplotlib/pyplot.py", line 962, in gca
    return gcf().gca(**kwargs)
  File "/usr/lib/python3/dist-packages/matplotlib/pyplot.py", line 592, in gcf
    return figure()
  File "/usr/lib/python3/dist-packages/matplotlib/pyplot.py", line 539, in figure
    **kwargs)
  File "/usr/lib/python3/dist-packages/matplotlib/backend_bases.py", line 171, in new_figure_manager
    return cls.new_figure_manager_given_figure(num, fig)
  File "/usr/lib/python3/dist-packages/matplotlib/backends/backend_tkagg.py", line 1049, in new_figure_manager_given_figure
    window = Tk.Tk(className="matplotlib")
  File "/usr/lib/python3.6/tkinter/__init__.py", line 2023, in __init__
    self.tk = _tkinter.create(screenName, baseName, className, interactive, wantobjects, useTk, sync, use)
_tkinter.TclError: couldn't connect to display "localhost:10.0"
url R1@100
Traceback (most recent call last):
  File "recall_time.py", line 47, in <module>
    plt.scatter([y for (x,y, z) in group_record if y > lower_bound], [math.log10(10000 / x * 1000) for (x,y, z) in group_record if y > lower_bound], marker='x', label=f'FLINNG' )
  File "/usr/lib/python3/dist-packages/matplotlib/pyplot.py", line 3364, in scatter
    ax = gca()
  File "/usr/lib/python3/dist-packages/matplotlib/pyplot.py", line 962, in gca
    return gcf().gca(**kwargs)
  File "/usr/lib/python3/dist-packages/matplotlib/pyplot.py", line 592, in gcf
    return figure()
  File "/usr/lib/python3/dist-packages/matplotlib/pyplot.py", line 539, in figure
    **kwargs)
  File "/usr/lib/python3/dist-packages/matplotlib/backend_bases.py", line 171, in new_figure_manager
    return cls.new_figure_manager_given_figure(num, fig)
  File "/usr/lib/python3/dist-packages/matplotlib/backends/backend_tkagg.py", line 1049, in new_figure_manager_given_figure
    window = Tk.Tk(className="matplotlib")
  File "/usr/lib/python3.6/tkinter/__init__.py", line 2023, in __init__
    self.tk = _tkinter.create(screenName, baseName, className, interactive, wantobjects, useTk, sync, use)
_tkinter.TclError: couldn't connect to display "localhost:10.0"
url R10@10
Traceback (most recent call last):
  File "recall_time.py", line 47, in <module>
    plt.scatter([y for (x,y, z) in group_record if y > lower_bound], [math.log10(10000 / x * 1000) for (x,y, z) in group_record if y > lower_bound], marker='x', label=f'FLINNG' )
  File "/usr/lib/python3/dist-packages/matplotlib/pyplot.py", line 3364, in scatter
    ax = gca()
  File "/usr/lib/python3/dist-packages/matplotlib/pyplot.py", line 962, in gca
    return gcf().gca(**kwargs)
  File "/usr/lib/python3/dist-packages/matplotlib/pyplot.py", line 592, in gcf
    return figure()
  File "/usr/lib/python3/dist-packages/matplotlib/pyplot.py", line 539, in figure
    **kwargs)
  File "/usr/lib/python3/dist-packages/matplotlib/backend_bases.py", line 171, in new_figure_manager
    return cls.new_figure_manager_given_figure(num, fig)
  File "/usr/lib/python3/dist-packages/matplotlib/backends/backend_tkagg.py", line 1049, in new_figure_manager_given_figure
    window = Tk.Tk(className="matplotlib")
  File "/usr/lib/python3.6/tkinter/__init__.py", line 2023, in __init__
    self.tk = _tkinter.create(screenName, baseName, className, interactive, wantobjects, useTk, sync, use)
_tkinter.TclError: couldn't connect to display "localhost:10.0"
url R10@100
Traceback (most recent call last):
  File "recall_time.py", line 47, in <module>
    plt.scatter([y for (x,y, z) in group_record if y > lower_bound], [math.log10(10000 / x * 1000) for (x,y, z) in group_record if y > lower_bound], marker='x', label=f'FLINNG' )
  File "/usr/lib/python3/dist-packages/matplotlib/pyplot.py", line 3364, in scatter
    ax = gca()
  File "/usr/lib/python3/dist-packages/matplotlib/pyplot.py", line 962, in gca
    return gcf().gca(**kwargs)
  File "/usr/lib/python3/dist-packages/matplotlib/pyplot.py", line 592, in gcf
    return figure()
  File "/usr/lib/python3/dist-packages/matplotlib/pyplot.py", line 539, in figure
    **kwargs)
  File "/usr/lib/python3/dist-packages/matplotlib/backend_bases.py", line 171, in new_figure_manager
    return cls.new_figure_manager_given_figure(num, fig)
  File "/usr/lib/python3/dist-packages/matplotlib/backends/backend_tkagg.py", line 1049, in new_figure_manager_given_figure
    window = Tk.Tk(className="matplotlib")
  File "/usr/lib/python3.6/tkinter/__init__.py", line 2023, in __init__
    self.tk = _tkinter.create(screenName, baseName, className, interactive, wantobjects, useTk, sync, use)
_tkinter.TclError: couldn't connect to display "localhost:10.0"
url R1@1
Traceback (most recent call last):
  File "recall_time.py", line 47, in <module>
    plt.scatter([y for (x,y, z) in group_record if y > lower_bound], [math.log10(10000 / x * 1000) for (x,y, z) in group_record if y > lower_bound], marker='x', label=f'FLINNG' )
  File "/usr/lib/python3/dist-packages/matplotlib/pyplot.py", line 3364, in scatter
    ax = gca()
  File "/usr/lib/python3/dist-packages/matplotlib/pyplot.py", line 962, in gca
    return gcf().gca(**kwargs)
  File "/usr/lib/python3/dist-packages/matplotlib/pyplot.py", line 592, in gcf
    return figure()
  File "/usr/lib/python3/dist-packages/matplotlib/pyplot.py", line 539, in figure
    **kwargs)
  File "/usr/lib/python3/dist-packages/matplotlib/backend_bases.py", line 171, in new_figure_manager
    return cls.new_figure_manager_given_figure(num, fig)
  File "/usr/lib/python3/dist-packages/matplotlib/backends/backend_tkagg.py", line 1049, in new_figure_manager_given_figure
    window = Tk.Tk(className="matplotlib")
  File "/usr/lib/python3.6/tkinter/__init__.py", line 2023, in __init__
    self.tk = _tkinter.create(screenName, baseName, className, interactive, wantobjects, useTk, sync, use)
_tkinter.TclError: couldn't connect to display "localhost:10.0"
url R1@10
Traceback (most recent call last):
  File "recall_time.py", line 47, in <module>
    plt.scatter([y for (x,y, z) in group_record if y > lower_bound], [math.log10(10000 / x * 1000) for (x,y, z) in group_record if y > lower_bound], marker='x', label=f'FLINNG' )
  File "/usr/lib/python3/dist-packages/matplotlib/pyplot.py", line 3364, in scatter
    ax = gca()
  File "/usr/lib/python3/dist-packages/matplotlib/pyplot.py", line 962, in gca
    return gcf().gca(**kwargs)
  File "/usr/lib/python3/dist-packages/matplotlib/pyplot.py", line 592, in gcf
    return figure()
  File "/usr/lib/python3/dist-packages/matplotlib/pyplot.py", line 539, in figure
    **kwargs)
  File "/usr/lib/python3/dist-packages/matplotlib/backend_bases.py", line 171, in new_figure_manager
    return cls.new_figure_manager_given_figure(num, fig)
  File "/usr/lib/python3/dist-packages/matplotlib/backends/backend_tkagg.py", line 1049, in new_figure_manager_given_figure
    window = Tk.Tk(className="matplotlib")
  File "/usr/lib/python3.6/tkinter/__init__.py", line 2023, in __init__
    self.tk = _tkinter.create(screenName, baseName, className, interactive, wantobjects, useTk, sync, use)
_tkinter.TclError: couldn't connect to display "localhost:10.0"
url R1@100
Traceback (most recent call last):
  File "recall_time.py", line 47, in <module>
    plt.scatter([y for (x,y, z) in group_record if y > lower_bound], [math.log10(10000 / x * 1000) for (x,y, z) in group_record if y > lower_bound], marker='x', label=f'FLINNG' )
  File "/usr/lib/python3/dist-packages/matplotlib/pyplot.py", line 3364, in scatter
    ax = gca()
  File "/usr/lib/python3/dist-packages/matplotlib/pyplot.py", line 962, in gca
    return gcf().gca(**kwargs)
  File "/usr/lib/python3/dist-packages/matplotlib/pyplot.py", line 592, in gcf
    return figure()
  File "/usr/lib/python3/dist-packages/matplotlib/pyplot.py", line 539, in figure
    **kwargs)
  File "/usr/lib/python3/dist-packages/matplotlib/backend_bases.py", line 171, in new_figure_manager
    return cls.new_figure_manager_given_figure(num, fig)
  File "/usr/lib/python3/dist-packages/matplotlib/backends/backend_tkagg.py", line 1049, in new_figure_manager_given_figure
    window = Tk.Tk(className="matplotlib")
  File "/usr/lib/python3.6/tkinter/__init__.py", line 2023, in __init__
    self.tk = _tkinter.create(screenName, baseName, className, interactive, wantobjects, useTk, sync, use)
_tkinter.TclError: couldn't connect to display "localhost:10.0"
url R10@10
Traceback (most recent call last):
  File "recall_time.py", line 47, in <module>
    plt.scatter([y for (x,y, z) in group_record if y > lower_bound], [math.log10(10000 / x * 1000) for (x,y, z) in group_record if y > lower_bound], marker='x', label=f'FLINNG' )
  File "/usr/lib/python3/dist-packages/matplotlib/pyplot.py", line 3364, in scatter
    ax = gca()
  File "/usr/lib/python3/dist-packages/matplotlib/pyplot.py", line 962, in gca
    return gcf().gca(**kwargs)
  File "/usr/lib/python3/dist-packages/matplotlib/pyplot.py", line 592, in gcf
    return figure()
  File "/usr/lib/python3/dist-packages/matplotlib/pyplot.py", line 539, in figure
    **kwargs)
  File "/usr/lib/python3/dist-packages/matplotlib/backend_bases.py", line 171, in new_figure_manager
    return cls.new_figure_manager_given_figure(num, fig)
  File "/usr/lib/python3/dist-packages/matplotlib/backends/backend_tkagg.py", line 1049, in new_figure_manager_given_figure
    window = Tk.Tk(className="matplotlib")
  File "/usr/lib/python3.6/tkinter/__init__.py", line 2023, in __init__
    self.tk = _tkinter.create(screenName, baseName, className, interactive, wantobjects, useTk, sync, use)
_tkinter.TclError: couldn't connect to display "localhost:10.0"
url R10@100
Traceback (most recent call last):
  File "recall_time.py", line 47, in <module>
    plt.scatter([y for (x,y, z) in group_record if y > lower_bound], [math.log10(10000 / x * 1000) for (x,y, z) in group_record if y > lower_bound], marker='x', label=f'FLINNG' )
  File "/usr/lib/python3/dist-packages/matplotlib/pyplot.py", line 3364, in scatter
    ax = gca()
  File "/usr/lib/python3/dist-packages/matplotlib/pyplot.py", line 962, in gca
    return gcf().gca(**kwargs)
  File "/usr/lib/python3/dist-packages/matplotlib/pyplot.py", line 592, in gcf
    return figure()
  File "/usr/lib/python3/dist-packages/matplotlib/pyplot.py", line 539, in figure
    **kwargs)
  File "/usr/lib/python3/dist-packages/matplotlib/backend_bases.py", line 171, in new_figure_manager
    return cls.new_figure_manager_given_figure(num, fig)
  File "/usr/lib/python3/dist-packages/matplotlib/backends/backend_tkagg.py", line 1049, in new_figure_manager_given_figure
    window = Tk.Tk(className="matplotlib")
  File "/usr/lib/python3.6/tkinter/__init__.py", line 2023, in __init__
    self.tk = _tkinter.create(screenName, baseName, className, interactive, wantobjects, useTk, sync, use)
_tkinter.TclError: couldn't connect to display "localhost:10.0"
genomes 2 1
Traceback (most recent call last):
  File "recall_precision.py", line 101, in <module>
    plt.scatter(group_record.values(), group_record.keys(), marker='x', label=f'FLINNG' )
  File "/usr/lib/python3/dist-packages/matplotlib/pyplot.py", line 3364, in scatter
    ax = gca()
  File "/usr/lib/python3/dist-packages/matplotlib/pyplot.py", line 962, in gca
    return gcf().gca(**kwargs)
  File "/usr/lib/python3/dist-packages/matplotlib/pyplot.py", line 592, in gcf
    return figure()
  File "/usr/lib/python3/dist-packages/matplotlib/pyplot.py", line 539, in figure
    **kwargs)
  File "/usr/lib/python3/dist-packages/matplotlib/backend_bases.py", line 171, in new_figure_manager
    return cls.new_figure_manager_given_figure(num, fig)
  File "/usr/lib/python3/dist-packages/matplotlib/backends/backend_tkagg.py", line 1049, in new_figure_manager_given_figure
    window = Tk.Tk(className="matplotlib")
  File "/usr/lib/python3.6/tkinter/__init__.py", line 2023, in __init__
    self.tk = _tkinter.create(screenName, baseName, className, interactive, wantobjects, useTk, sync, use)
_tkinter.TclError: couldn't connect to display "localhost:10.0"
genomes 2 10
Traceback (most recent call last):
  File "recall_precision.py", line 101, in <module>
    plt.scatter(group_record.values(), group_record.keys(), marker='x', label=f'FLINNG' )
  File "/usr/lib/python3/dist-packages/matplotlib/pyplot.py", line 3364, in scatter
    ax = gca()
  File "/usr/lib/python3/dist-packages/matplotlib/pyplot.py", line 962, in gca
    return gcf().gca(**kwargs)
  File "/usr/lib/python3/dist-packages/matplotlib/pyplot.py", line 592, in gcf
    return figure()
  File "/usr/lib/python3/dist-packages/matplotlib/pyplot.py", line 539, in figure
    **kwargs)
  File "/usr/lib/python3/dist-packages/matplotlib/backend_bases.py", line 171, in new_figure_manager
    return cls.new_figure_manager_given_figure(num, fig)
  File "/usr/lib/python3/dist-packages/matplotlib/backends/backend_tkagg.py", line 1049, in new_figure_manager_given_figure
    window = Tk.Tk(className="matplotlib")
  File "/usr/lib/python3.6/tkinter/__init__.py", line 2023, in __init__
    self.tk = _tkinter.create(screenName, baseName, className, interactive, wantobjects, useTk, sync, use)
_tkinter.TclError: couldn't connect to display "localhost:10.0"
genomes 20 1
Traceback (most recent call last):
  File "recall_precision.py", line 101, in <module>
    plt.scatter(group_record.values(), group_record.keys(), marker='x', label=f'FLINNG' )
  File "/usr/lib/python3/dist-packages/matplotlib/pyplot.py", line 3364, in scatter
    ax = gca()
  File "/usr/lib/python3/dist-packages/matplotlib/pyplot.py", line 962, in gca
    return gcf().gca(**kwargs)
  File "/usr/lib/python3/dist-packages/matplotlib/pyplot.py", line 592, in gcf
    return figure()
  File "/usr/lib/python3/dist-packages/matplotlib/pyplot.py", line 539, in figure
    **kwargs)
  File "/usr/lib/python3/dist-packages/matplotlib/backend_bases.py", line 171, in new_figure_manager
    return cls.new_figure_manager_given_figure(num, fig)
  File "/usr/lib/python3/dist-packages/matplotlib/backends/backend_tkagg.py", line 1049, in new_figure_manager_given_figure
    window = Tk.Tk(className="matplotlib")
  File "/usr/lib/python3.6/tkinter/__init__.py", line 2023, in __init__
    self.tk = _tkinter.create(screenName, baseName, className, interactive, wantobjects, useTk, sync, use)
_tkinter.TclError: couldn't connect to display "localhost:10.0"
genomes 20 10
Traceback (most recent call last):
  File "recall_precision.py", line 101, in <module>
    plt.scatter(group_record.values(), group_record.keys(), marker='x', label=f'FLINNG' )
  File "/usr/lib/python3/dist-packages/matplotlib/pyplot.py", line 3364, in scatter
    ax = gca()
  File "/usr/lib/python3/dist-packages/matplotlib/pyplot.py", line 962, in gca
    return gcf().gca(**kwargs)
  File "/usr/lib/python3/dist-packages/matplotlib/pyplot.py", line 592, in gcf
    return figure()
  File "/usr/lib/python3/dist-packages/matplotlib/pyplot.py", line 539, in figure
    **kwargs)
  File "/usr/lib/python3/dist-packages/matplotlib/backend_bases.py", line 171, in new_figure_manager
    return cls.new_figure_manager_given_figure(num, fig)
  File "/usr/lib/python3/dist-packages/matplotlib/backends/backend_tkagg.py", line 1049, in new_figure_manager_given_figure
    window = Tk.Tk(className="matplotlib")
  File "/usr/lib/python3.6/tkinter/__init__.py", line 2023, in __init__
    self.tk = _tkinter.create(screenName, baseName, className, interactive, wantobjects, useTk, sync, use)
_tkinter.TclError: couldn't connect to display "localhost:10.0"
genomes 200 1
Traceback (most recent call last):
  File "recall_precision.py", line 101, in <module>
    plt.scatter(group_record.values(), group_record.keys(), marker='x', label=f'FLINNG' )
  File "/usr/lib/python3/dist-packages/matplotlib/pyplot.py", line 3364, in scatter
    ax = gca()
  File "/usr/lib/python3/dist-packages/matplotlib/pyplot.py", line 962, in gca
    return gcf().gca(**kwargs)
  File "/usr/lib/python3/dist-packages/matplotlib/pyplot.py", line 592, in gcf
    return figure()
  File "/usr/lib/python3/dist-packages/matplotlib/pyplot.py", line 539, in figure
    **kwargs)
  File "/usr/lib/python3/dist-packages/matplotlib/backend_bases.py", line 171, in new_figure_manager
    return cls.new_figure_manager_given_figure(num, fig)
  File "/usr/lib/python3/dist-packages/matplotlib/backends/backend_tkagg.py", line 1049, in new_figure_manager_given_figure
    window = Tk.Tk(className="matplotlib")
  File "/usr/lib/python3.6/tkinter/__init__.py", line 2023, in __init__
    self.tk = _tkinter.create(screenName, baseName, className, interactive, wantobjects, useTk, sync, use)
_tkinter.TclError: couldn't connect to display "localhost:10.0"
genomes 200 10
Traceback (most recent call last):
  File "recall_precision.py", line 101, in <module>
    plt.scatter(group_record.values(), group_record.keys(), marker='x', label=f'FLINNG' )
  File "/usr/lib/python3/dist-packages/matplotlib/pyplot.py", line 3364, in scatter
    ax = gca()
  File "/usr/lib/python3/dist-packages/matplotlib/pyplot.py", line 962, in gca
    return gcf().gca(**kwargs)
  File "/usr/lib/python3/dist-packages/matplotlib/pyplot.py", line 592, in gcf
    return figure()
  File "/usr/lib/python3/dist-packages/matplotlib/pyplot.py", line 539, in figure
    **kwargs)
  File "/usr/lib/python3/dist-packages/matplotlib/backend_bases.py", line 171, in new_figure_manager
    return cls.new_figure_manager_given_figure(num, fig)
  File "/usr/lib/python3/dist-packages/matplotlib/backends/backend_tkagg.py", line 1049, in new_figure_manager_given_figure
    window = Tk.Tk(className="matplotlib")
  File "/usr/lib/python3.6/tkinter/__init__.py", line 2023, in __init__
    self.tk = _tkinter.create(screenName, baseName, className, interactive, wantobjects, useTk, sync, use)
_tkinter.TclError: couldn't connect to display "localhost:10.0"
genomes R1@1
Traceback (most recent call last):
  File "recall_time.py", line 47, in <module>
    plt.scatter([y for (x,y, z) in group_record if y > lower_bound], [math.log10(10000 / x * 1000) for (x,y, z) in group_record if y > lower_bound], marker='x', label=f'FLINNG' )
  File "/usr/lib/python3/dist-packages/matplotlib/pyplot.py", line 3364, in scatter
    ax = gca()
  File "/usr/lib/python3/dist-packages/matplotlib/pyplot.py", line 962, in gca
    return gcf().gca(**kwargs)
  File "/usr/lib/python3/dist-packages/matplotlib/pyplot.py", line 592, in gcf
    return figure()
  File "/usr/lib/python3/dist-packages/matplotlib/pyplot.py", line 539, in figure
    **kwargs)
  File "/usr/lib/python3/dist-packages/matplotlib/backend_bases.py", line 171, in new_figure_manager
    return cls.new_figure_manager_given_figure(num, fig)
  File "/usr/lib/python3/dist-packages/matplotlib/backends/backend_tkagg.py", line 1049, in new_figure_manager_given_figure
    window = Tk.Tk(className="matplotlib")
  File "/usr/lib/python3.6/tkinter/__init__.py", line 2023, in __init__
    self.tk = _tkinter.create(screenName, baseName, className, interactive, wantobjects, useTk, sync, use)
_tkinter.TclError: couldn't connect to display "localhost:10.0"
genomes R1@10
Traceback (most recent call last):
  File "recall_time.py", line 47, in <module>
    plt.scatter([y for (x,y, z) in group_record if y > lower_bound], [math.log10(10000 / x * 1000) for (x,y, z) in group_record if y > lower_bound], marker='x', label=f'FLINNG' )
  File "/usr/lib/python3/dist-packages/matplotlib/pyplot.py", line 3364, in scatter
    ax = gca()
  File "/usr/lib/python3/dist-packages/matplotlib/pyplot.py", line 962, in gca
    return gcf().gca(**kwargs)
  File "/usr/lib/python3/dist-packages/matplotlib/pyplot.py", line 592, in gcf
    return figure()
  File "/usr/lib/python3/dist-packages/matplotlib/pyplot.py", line 539, in figure
    **kwargs)
  File "/usr/lib/python3/dist-packages/matplotlib/backend_bases.py", line 171, in new_figure_manager
    return cls.new_figure_manager_given_figure(num, fig)
  File "/usr/lib/python3/dist-packages/matplotlib/backends/backend_tkagg.py", line 1049, in new_figure_manager_given_figure
    window = Tk.Tk(className="matplotlib")
  File "/usr/lib/python3.6/tkinter/__init__.py", line 2023, in __init__
    self.tk = _tkinter.create(screenName, baseName, className, interactive, wantobjects, useTk, sync, use)
_tkinter.TclError: couldn't connect to display "localhost:10.0"
genomes R1@100
Traceback (most recent call last):
  File "recall_time.py", line 47, in <module>
    plt.scatter([y for (x,y, z) in group_record if y > lower_bound], [math.log10(10000 / x * 1000) for (x,y, z) in group_record if y > lower_bound], marker='x', label=f'FLINNG' )
  File "/usr/lib/python3/dist-packages/matplotlib/pyplot.py", line 3364, in scatter
    ax = gca()
  File "/usr/lib/python3/dist-packages/matplotlib/pyplot.py", line 962, in gca
    return gcf().gca(**kwargs)
  File "/usr/lib/python3/dist-packages/matplotlib/pyplot.py", line 592, in gcf
    return figure()
  File "/usr/lib/python3/dist-packages/matplotlib/pyplot.py", line 539, in figure
    **kwargs)
  File "/usr/lib/python3/dist-packages/matplotlib/backend_bases.py", line 171, in new_figure_manager
    return cls.new_figure_manager_given_figure(num, fig)
  File "/usr/lib/python3/dist-packages/matplotlib/backends/backend_tkagg.py", line 1049, in new_figure_manager_given_figure
    window = Tk.Tk(className="matplotlib")
  File "/usr/lib/python3.6/tkinter/__init__.py", line 2023, in __init__
    self.tk = _tkinter.create(screenName, baseName, className, interactive, wantobjects, useTk, sync, use)
_tkinter.TclError: couldn't connect to display "localhost:10.0"
genomes R10@10
Traceback (most recent call last):
  File "recall_time.py", line 47, in <module>
    plt.scatter([y for (x,y, z) in group_record if y > lower_bound], [math.log10(10000 / x * 1000) for (x,y, z) in group_record if y > lower_bound], marker='x', label=f'FLINNG' )
  File "/usr/lib/python3/dist-packages/matplotlib/pyplot.py", line 3364, in scatter
    ax = gca()
  File "/usr/lib/python3/dist-packages/matplotlib/pyplot.py", line 962, in gca
    return gcf().gca(**kwargs)
  File "/usr/lib/python3/dist-packages/matplotlib/pyplot.py", line 592, in gcf
    return figure()
  File "/usr/lib/python3/dist-packages/matplotlib/pyplot.py", line 539, in figure
    **kwargs)
  File "/usr/lib/python3/dist-packages/matplotlib/backend_bases.py", line 171, in new_figure_manager
    return cls.new_figure_manager_given_figure(num, fig)
  File "/usr/lib/python3/dist-packages/matplotlib/backends/backend_tkagg.py", line 1049, in new_figure_manager_given_figure
    window = Tk.Tk(className="matplotlib")
  File "/usr/lib/python3.6/tkinter/__init__.py", line 2023, in __init__
    self.tk = _tkinter.create(screenName, baseName, className, interactive, wantobjects, useTk, sync, use)
_tkinter.TclError: couldn't connect to display "localhost:10.0"
genomes R10@100
Traceback (most recent call last):
  File "recall_time.py", line 47, in <module>
    plt.scatter([y for (x,y, z) in group_record if y > lower_bound], [math.log10(10000 / x * 1000) for (x,y, z) in group_record if y > lower_bound], marker='x', label=f'FLINNG' )
  File "/usr/lib/python3/dist-packages/matplotlib/pyplot.py", line 3364, in scatter
    ax = gca()
  File "/usr/lib/python3/dist-packages/matplotlib/pyplot.py", line 962, in gca
    return gcf().gca(**kwargs)
  File "/usr/lib/python3/dist-packages/matplotlib/pyplot.py", line 592, in gcf
    return figure()
  File "/usr/lib/python3/dist-packages/matplotlib/pyplot.py", line 539, in figure
    **kwargs)
  File "/usr/lib/python3/dist-packages/matplotlib/backend_bases.py", line 171, in new_figure_manager
    return cls.new_figure_manager_given_figure(num, fig)
  File "/usr/lib/python3/dist-packages/matplotlib/backends/backend_tkagg.py", line 1049, in new_figure_manager_given_figure
    window = Tk.Tk(className="matplotlib")
  File "/usr/lib/python3.6/tkinter/__init__.py", line 2023, in __init__
    self.tk = _tkinter.create(screenName, baseName, className, interactive, wantobjects, useTk, sync, use)
_tkinter.TclError: couldn't connect to display "localhost:10.0"
genomes R1@1
Traceback (most recent call last):
  File "recall_time.py", line 47, in <module>
    plt.scatter([y for (x,y, z) in group_record if y > lower_bound], [math.log10(10000 / x * 1000) for (x,y, z) in group_record if y > lower_bound], marker='x', label=f'FLINNG' )
  File "/usr/lib/python3/dist-packages/matplotlib/pyplot.py", line 3364, in scatter
    ax = gca()
  File "/usr/lib/python3/dist-packages/matplotlib/pyplot.py", line 962, in gca
    return gcf().gca(**kwargs)
  File "/usr/lib/python3/dist-packages/matplotlib/pyplot.py", line 592, in gcf
    return figure()
  File "/usr/lib/python3/dist-packages/matplotlib/pyplot.py", line 539, in figure
    **kwargs)
  File "/usr/lib/python3/dist-packages/matplotlib/backend_bases.py", line 171, in new_figure_manager
    return cls.new_figure_manager_given_figure(num, fig)
  File "/usr/lib/python3/dist-packages/matplotlib/backends/backend_tkagg.py", line 1049, in new_figure_manager_given_figure
    window = Tk.Tk(className="matplotlib")
  File "/usr/lib/python3.6/tkinter/__init__.py", line 2023, in __init__
    self.tk = _tkinter.create(screenName, baseName, className, interactive, wantobjects, useTk, sync, use)
_tkinter.TclError: couldn't connect to display "localhost:10.0"
genomes R1@10
Traceback (most recent call last):
  File "recall_time.py", line 47, in <module>
    plt.scatter([y for (x,y, z) in group_record if y > lower_bound], [math.log10(10000 / x * 1000) for (x,y, z) in group_record if y > lower_bound], marker='x', label=f'FLINNG' )
  File "/usr/lib/python3/dist-packages/matplotlib/pyplot.py", line 3364, in scatter
    ax = gca()
  File "/usr/lib/python3/dist-packages/matplotlib/pyplot.py", line 962, in gca
    return gcf().gca(**kwargs)
  File "/usr/lib/python3/dist-packages/matplotlib/pyplot.py", line 592, in gcf
    return figure()
  File "/usr/lib/python3/dist-packages/matplotlib/pyplot.py", line 539, in figure
    **kwargs)
  File "/usr/lib/python3/dist-packages/matplotlib/backend_bases.py", line 171, in new_figure_manager
    return cls.new_figure_manager_given_figure(num, fig)
  File "/usr/lib/python3/dist-packages/matplotlib/backends/backend_tkagg.py", line 1049, in new_figure_manager_given_figure
    window = Tk.Tk(className="matplotlib")
  File "/usr/lib/python3.6/tkinter/__init__.py", line 2023, in __init__
    self.tk = _tkinter.create(screenName, baseName, className, interactive, wantobjects, useTk, sync, use)
_tkinter.TclError: couldn't connect to display "localhost:10.0"
genomes R1@100
Traceback (most recent call last):
  File "recall_time.py", line 47, in <module>
    plt.scatter([y for (x,y, z) in group_record if y > lower_bound], [math.log10(10000 / x * 1000) for (x,y, z) in group_record if y > lower_bound], marker='x', label=f'FLINNG' )
  File "/usr/lib/python3/dist-packages/matplotlib/pyplot.py", line 3364, in scatter
    ax = gca()
  File "/usr/lib/python3/dist-packages/matplotlib/pyplot.py", line 962, in gca
    return gcf().gca(**kwargs)
  File "/usr/lib/python3/dist-packages/matplotlib/pyplot.py", line 592, in gcf
    return figure()
  File "/usr/lib/python3/dist-packages/matplotlib/pyplot.py", line 539, in figure
    **kwargs)
  File "/usr/lib/python3/dist-packages/matplotlib/backend_bases.py", line 171, in new_figure_manager
    return cls.new_figure_manager_given_figure(num, fig)
  File "/usr/lib/python3/dist-packages/matplotlib/backends/backend_tkagg.py", line 1049, in new_figure_manager_given_figure
    window = Tk.Tk(className="matplotlib")
  File "/usr/lib/python3.6/tkinter/__init__.py", line 2023, in __init__
    self.tk = _tkinter.create(screenName, baseName, className, interactive, wantobjects, useTk, sync, use)
_tkinter.TclError: couldn't connect to display "localhost:10.0"
genomes R10@10
Traceback (most recent call last):
  File "recall_time.py", line 47, in <module>
    plt.scatter([y for (x,y, z) in group_record if y > lower_bound], [math.log10(10000 / x * 1000) for (x,y, z) in group_record if y > lower_bound], marker='x', label=f'FLINNG' )
  File "/usr/lib/python3/dist-packages/matplotlib/pyplot.py", line 3364, in scatter
    ax = gca()
  File "/usr/lib/python3/dist-packages/matplotlib/pyplot.py", line 962, in gca
    return gcf().gca(**kwargs)
  File "/usr/lib/python3/dist-packages/matplotlib/pyplot.py", line 592, in gcf
    return figure()
  File "/usr/lib/python3/dist-packages/matplotlib/pyplot.py", line 539, in figure
    **kwargs)
  File "/usr/lib/python3/dist-packages/matplotlib/backend_bases.py", line 171, in new_figure_manager
    return cls.new_figure_manager_given_figure(num, fig)
  File "/usr/lib/python3/dist-packages/matplotlib/backends/backend_tkagg.py", line 1049, in new_figure_manager_given_figure
    window = Tk.Tk(className="matplotlib")
  File "/usr/lib/python3.6/tkinter/__init__.py", line 2023, in __init__
    self.tk = _tkinter.create(screenName, baseName, className, interactive, wantobjects, useTk, sync, use)
_tkinter.TclError: couldn't connect to display "localhost:10.0"
genomes R10@100
Traceback (most recent call last):
  File "recall_time.py", line 47, in <module>
    plt.scatter([y for (x,y, z) in group_record if y > lower_bound], [math.log10(10000 / x * 1000) for (x,y, z) in group_record if y > lower_bound], marker='x', label=f'FLINNG' )
  File "/usr/lib/python3/dist-packages/matplotlib/pyplot.py", line 3364, in scatter
    ax = gca()
  File "/usr/lib/python3/dist-packages/matplotlib/pyplot.py", line 962, in gca
    return gcf().gca(**kwargs)
  File "/usr/lib/python3/dist-packages/matplotlib/pyplot.py", line 592, in gcf
    return figure()
  File "/usr/lib/python3/dist-packages/matplotlib/pyplot.py", line 539, in figure
    **kwargs)
  File "/usr/lib/python3/dist-packages/matplotlib/backend_bases.py", line 171, in new_figure_manager
    return cls.new_figure_manager_given_figure(num, fig)
  File "/usr/lib/python3/dist-packages/matplotlib/backends/backend_tkagg.py", line 1049, in new_figure_manager_given_figure
    window = Tk.Tk(className="matplotlib")
  File "/usr/lib/python3.6/tkinter/__init__.py", line 2023, in __init__
    self.tk = _tkinter.create(screenName, baseName, className, interactive, wantobjects, useTk, sync, use)
_tkinter.TclError: couldn't connect to display "localhost:10.0"
proteomes 2 1
Traceback (most recent call last):
  File "recall_precision.py", line 101, in <module>
    plt.scatter(group_record.values(), group_record.keys(), marker='x', label=f'FLINNG' )
  File "/usr/lib/python3/dist-packages/matplotlib/pyplot.py", line 3364, in scatter
    ax = gca()
  File "/usr/lib/python3/dist-packages/matplotlib/pyplot.py", line 962, in gca
    return gcf().gca(**kwargs)
  File "/usr/lib/python3/dist-packages/matplotlib/pyplot.py", line 592, in gcf
    return figure()
  File "/usr/lib/python3/dist-packages/matplotlib/pyplot.py", line 539, in figure
    **kwargs)
  File "/usr/lib/python3/dist-packages/matplotlib/backend_bases.py", line 171, in new_figure_manager
    return cls.new_figure_manager_given_figure(num, fig)
  File "/usr/lib/python3/dist-packages/matplotlib/backends/backend_tkagg.py", line 1049, in new_figure_manager_given_figure
    window = Tk.Tk(className="matplotlib")
  File "/usr/lib/python3.6/tkinter/__init__.py", line 2023, in __init__
    self.tk = _tkinter.create(screenName, baseName, className, interactive, wantobjects, useTk, sync, use)
_tkinter.TclError: couldn't connect to display "localhost:10.0"
proteomes 2 10
Traceback (most recent call last):
  File "recall_precision.py", line 101, in <module>
    plt.scatter(group_record.values(), group_record.keys(), marker='x', label=f'FLINNG' )
  File "/usr/lib/python3/dist-packages/matplotlib/pyplot.py", line 3364, in scatter
    ax = gca()
  File "/usr/lib/python3/dist-packages/matplotlib/pyplot.py", line 962, in gca
    return gcf().gca(**kwargs)
  File "/usr/lib/python3/dist-packages/matplotlib/pyplot.py", line 592, in gcf
    return figure()
  File "/usr/lib/python3/dist-packages/matplotlib/pyplot.py", line 539, in figure
    **kwargs)
  File "/usr/lib/python3/dist-packages/matplotlib/backend_bases.py", line 171, in new_figure_manager
    return cls.new_figure_manager_given_figure(num, fig)
  File "/usr/lib/python3/dist-packages/matplotlib/backends/backend_tkagg.py", line 1049, in new_figure_manager_given_figure
    window = Tk.Tk(className="matplotlib")
  File "/usr/lib/python3.6/tkinter/__init__.py", line 2023, in __init__
    self.tk = _tkinter.create(screenName, baseName, className, interactive, wantobjects, useTk, sync, use)
_tkinter.TclError: couldn't connect to display "localhost:10.0"
proteomes 20 1
Traceback (most recent call last):
  File "recall_precision.py", line 101, in <module>
    plt.scatter(group_record.values(), group_record.keys(), marker='x', label=f'FLINNG' )
  File "/usr/lib/python3/dist-packages/matplotlib/pyplot.py", line 3364, in scatter
    ax = gca()
  File "/usr/lib/python3/dist-packages/matplotlib/pyplot.py", line 962, in gca
    return gcf().gca(**kwargs)
  File "/usr/lib/python3/dist-packages/matplotlib/pyplot.py", line 592, in gcf
    return figure()
  File "/usr/lib/python3/dist-packages/matplotlib/pyplot.py", line 539, in figure
    **kwargs)
  File "/usr/lib/python3/dist-packages/matplotlib/backend_bases.py", line 171, in new_figure_manager
    return cls.new_figure_manager_given_figure(num, fig)
  File "/usr/lib/python3/dist-packages/matplotlib/backends/backend_tkagg.py", line 1049, in new_figure_manager_given_figure
    window = Tk.Tk(className="matplotlib")
  File "/usr/lib/python3.6/tkinter/__init__.py", line 2023, in __init__
    self.tk = _tkinter.create(screenName, baseName, className, interactive, wantobjects, useTk, sync, use)
_tkinter.TclError: couldn't connect to display "localhost:10.0"
proteomes 20 10
Traceback (most recent call last):
  File "recall_precision.py", line 101, in <module>
    plt.scatter(group_record.values(), group_record.keys(), marker='x', label=f'FLINNG' )
  File "/usr/lib/python3/dist-packages/matplotlib/pyplot.py", line 3364, in scatter
    ax = gca()
  File "/usr/lib/python3/dist-packages/matplotlib/pyplot.py", line 962, in gca
    return gcf().gca(**kwargs)
  File "/usr/lib/python3/dist-packages/matplotlib/pyplot.py", line 592, in gcf
    return figure()
  File "/usr/lib/python3/dist-packages/matplotlib/pyplot.py", line 539, in figure
    **kwargs)
  File "/usr/lib/python3/dist-packages/matplotlib/backend_bases.py", line 171, in new_figure_manager
    return cls.new_figure_manager_given_figure(num, fig)
  File "/usr/lib/python3/dist-packages/matplotlib/backends/backend_tkagg.py", line 1049, in new_figure_manager_given_figure
    window = Tk.Tk(className="matplotlib")
  File "/usr/lib/python3.6/tkinter/__init__.py", line 2023, in __init__
    self.tk = _tkinter.create(screenName, baseName, className, interactive, wantobjects, useTk, sync, use)
_tkinter.TclError: couldn't connect to display "localhost:10.0"
proteomes 200 1
Traceback (most recent call last):
  File "recall_precision.py", line 101, in <module>
    plt.scatter(group_record.values(), group_record.keys(), marker='x', label=f'FLINNG' )
  File "/usr/lib/python3/dist-packages/matplotlib/pyplot.py", line 3364, in scatter
    ax = gca()
  File "/usr/lib/python3/dist-packages/matplotlib/pyplot.py", line 962, in gca
    return gcf().gca(**kwargs)
  File "/usr/lib/python3/dist-packages/matplotlib/pyplot.py", line 592, in gcf
    return figure()
  File "/usr/lib/python3/dist-packages/matplotlib/pyplot.py", line 539, in figure
    **kwargs)
  File "/usr/lib/python3/dist-packages/matplotlib/backend_bases.py", line 171, in new_figure_manager
    return cls.new_figure_manager_given_figure(num, fig)
  File "/usr/lib/python3/dist-packages/matplotlib/backends/backend_tkagg.py", line 1049, in new_figure_manager_given_figure
    window = Tk.Tk(className="matplotlib")
  File "/usr/lib/python3.6/tkinter/__init__.py", line 2023, in __init__
    self.tk = _tkinter.create(screenName, baseName, className, interactive, wantobjects, useTk, sync, use)
_tkinter.TclError: couldn't connect to display "localhost:10.0"
proteomes 200 10
Traceback (most recent call last):
  File "recall_precision.py", line 101, in <module>
    plt.scatter(group_record.values(), group_record.keys(), marker='x', label=f'FLINNG' )
  File "/usr/lib/python3/dist-packages/matplotlib/pyplot.py", line 3364, in scatter
    ax = gca()
  File "/usr/lib/python3/dist-packages/matplotlib/pyplot.py", line 962, in gca
    return gcf().gca(**kwargs)
  File "/usr/lib/python3/dist-packages/matplotlib/pyplot.py", line 592, in gcf
    return figure()
  File "/usr/lib/python3/dist-packages/matplotlib/pyplot.py", line 539, in figure
    **kwargs)
  File "/usr/lib/python3/dist-packages/matplotlib/backend_bases.py", line 171, in new_figure_manager
    return cls.new_figure_manager_given_figure(num, fig)
  File "/usr/lib/python3/dist-packages/matplotlib/backends/backend_tkagg.py", line 1049, in new_figure_manager_given_figure
    window = Tk.Tk(className="matplotlib")
  File "/usr/lib/python3.6/tkinter/__init__.py", line 2023, in __init__
    self.tk = _tkinter.create(screenName, baseName, className, interactive, wantobjects, useTk, sync, use)
_tkinter.TclError: couldn't connect to display "localhost:10.0"
proteomes R1@1
Traceback (most recent call last):
  File "recall_time.py", line 47, in <module>
    plt.scatter([y for (x,y, z) in group_record if y > lower_bound], [math.log10(10000 / x * 1000) for (x,y, z) in group_record if y > lower_bound], marker='x', label=f'FLINNG' )
  File "/usr/lib/python3/dist-packages/matplotlib/pyplot.py", line 3364, in scatter
    ax = gca()
  File "/usr/lib/python3/dist-packages/matplotlib/pyplot.py", line 962, in gca
    return gcf().gca(**kwargs)
  File "/usr/lib/python3/dist-packages/matplotlib/pyplot.py", line 592, in gcf
    return figure()
  File "/usr/lib/python3/dist-packages/matplotlib/pyplot.py", line 539, in figure
    **kwargs)
  File "/usr/lib/python3/dist-packages/matplotlib/backend_bases.py", line 171, in new_figure_manager
    return cls.new_figure_manager_given_figure(num, fig)
  File "/usr/lib/python3/dist-packages/matplotlib/backends/backend_tkagg.py", line 1049, in new_figure_manager_given_figure
    window = Tk.Tk(className="matplotlib")
  File "/usr/lib/python3.6/tkinter/__init__.py", line 2023, in __init__
    self.tk = _tkinter.create(screenName, baseName, className, interactive, wantobjects, useTk, sync, use)
_tkinter.TclError: couldn't connect to display "localhost:10.0"
proteomes R1@10
Traceback (most recent call last):
  File "recall_time.py", line 47, in <module>
    plt.scatter([y for (x,y, z) in group_record if y > lower_bound], [math.log10(10000 / x * 1000) for (x,y, z) in group_record if y > lower_bound], marker='x', label=f'FLINNG' )
  File "/usr/lib/python3/dist-packages/matplotlib/pyplot.py", line 3364, in scatter
    ax = gca()
  File "/usr/lib/python3/dist-packages/matplotlib/pyplot.py", line 962, in gca
    return gcf().gca(**kwargs)
  File "/usr/lib/python3/dist-packages/matplotlib/pyplot.py", line 592, in gcf
    return figure()
  File "/usr/lib/python3/dist-packages/matplotlib/pyplot.py", line 539, in figure
    **kwargs)
  File "/usr/lib/python3/dist-packages/matplotlib/backend_bases.py", line 171, in new_figure_manager
    return cls.new_figure_manager_given_figure(num, fig)
  File "/usr/lib/python3/dist-packages/matplotlib/backends/backend_tkagg.py", line 1049, in new_figure_manager_given_figure
    window = Tk.Tk(className="matplotlib")
  File "/usr/lib/python3.6/tkinter/__init__.py", line 2023, in __init__
    self.tk = _tkinter.create(screenName, baseName, className, interactive, wantobjects, useTk, sync, use)
_tkinter.TclError: couldn't connect to display "localhost:10.0"
proteomes R1@100
Traceback (most recent call last):
  File "recall_time.py", line 47, in <module>
    plt.scatter([y for (x,y, z) in group_record if y > lower_bound], [math.log10(10000 / x * 1000) for (x,y, z) in group_record if y > lower_bound], marker='x', label=f'FLINNG' )
  File "/usr/lib/python3/dist-packages/matplotlib/pyplot.py", line 3364, in scatter
    ax = gca()
  File "/usr/lib/python3/dist-packages/matplotlib/pyplot.py", line 962, in gca
    return gcf().gca(**kwargs)
  File "/usr/lib/python3/dist-packages/matplotlib/pyplot.py", line 592, in gcf
    return figure()
  File "/usr/lib/python3/dist-packages/matplotlib/pyplot.py", line 539, in figure
    **kwargs)
  File "/usr/lib/python3/dist-packages/matplotlib/backend_bases.py", line 171, in new_figure_manager
    return cls.new_figure_manager_given_figure(num, fig)
  File "/usr/lib/python3/dist-packages/matplotlib/backends/backend_tkagg.py", line 1049, in new_figure_manager_given_figure
    window = Tk.Tk(className="matplotlib")
  File "/usr/lib/python3.6/tkinter/__init__.py", line 2023, in __init__
    self.tk = _tkinter.create(screenName, baseName, className, interactive, wantobjects, useTk, sync, use)
_tkinter.TclError: couldn't connect to display "localhost:10.0"
proteomes R10@10
Traceback (most recent call last):
  File "recall_time.py", line 47, in <module>
    plt.scatter([y for (x,y, z) in group_record if y > lower_bound], [math.log10(10000 / x * 1000) for (x,y, z) in group_record if y > lower_bound], marker='x', label=f'FLINNG' )
  File "/usr/lib/python3/dist-packages/matplotlib/pyplot.py", line 3364, in scatter
    ax = gca()
  File "/usr/lib/python3/dist-packages/matplotlib/pyplot.py", line 962, in gca
    return gcf().gca(**kwargs)
  File "/usr/lib/python3/dist-packages/matplotlib/pyplot.py", line 592, in gcf
    return figure()
  File "/usr/lib/python3/dist-packages/matplotlib/pyplot.py", line 539, in figure
    **kwargs)
  File "/usr/lib/python3/dist-packages/matplotlib/backend_bases.py", line 171, in new_figure_manager
    return cls.new_figure_manager_given_figure(num, fig)
  File "/usr/lib/python3/dist-packages/matplotlib/backends/backend_tkagg.py", line 1049, in new_figure_manager_given_figure
    window = Tk.Tk(className="matplotlib")
  File "/usr/lib/python3.6/tkinter/__init__.py", line 2023, in __init__
    self.tk = _tkinter.create(screenName, baseName, className, interactive, wantobjects, useTk, sync, use)
_tkinter.TclError: couldn't connect to display "localhost:10.0"
proteomes R10@100
Traceback (most recent call last):
  File "recall_time.py", line 47, in <module>
    plt.scatter([y for (x,y, z) in group_record if y > lower_bound], [math.log10(10000 / x * 1000) for (x,y, z) in group_record if y > lower_bound], marker='x', label=f'FLINNG' )
  File "/usr/lib/python3/dist-packages/matplotlib/pyplot.py", line 3364, in scatter
    ax = gca()
  File "/usr/lib/python3/dist-packages/matplotlib/pyplot.py", line 962, in gca
    return gcf().gca(**kwargs)
  File "/usr/lib/python3/dist-packages/matplotlib/pyplot.py", line 592, in gcf
    return figure()
  File "/usr/lib/python3/dist-packages/matplotlib/pyplot.py", line 539, in figure
    **kwargs)
  File "/usr/lib/python3/dist-packages/matplotlib/backend_bases.py", line 171, in new_figure_manager
    return cls.new_figure_manager_given_figure(num, fig)
  File "/usr/lib/python3/dist-packages/matplotlib/backends/backend_tkagg.py", line 1049, in new_figure_manager_given_figure
    window = Tk.Tk(className="matplotlib")
  File "/usr/lib/python3.6/tkinter/__init__.py", line 2023, in __init__
    self.tk = _tkinter.create(screenName, baseName, className, interactive, wantobjects, useTk, sync, use)
_tkinter.TclError: couldn't connect to display "localhost:10.0"
proteomes R1@1
Traceback (most recent call last):
  File "recall_time.py", line 47, in <module>
    plt.scatter([y for (x,y, z) in group_record if y > lower_bound], [math.log10(10000 / x * 1000) for (x,y, z) in group_record if y > lower_bound], marker='x', label=f'FLINNG' )
  File "/usr/lib/python3/dist-packages/matplotlib/pyplot.py", line 3364, in scatter
    ax = gca()
  File "/usr/lib/python3/dist-packages/matplotlib/pyplot.py", line 962, in gca
    return gcf().gca(**kwargs)
  File "/usr/lib/python3/dist-packages/matplotlib/pyplot.py", line 592, in gcf
    return figure()
  File "/usr/lib/python3/dist-packages/matplotlib/pyplot.py", line 539, in figure
    **kwargs)
  File "/usr/lib/python3/dist-packages/matplotlib/backend_bases.py", line 171, in new_figure_manager
    return cls.new_figure_manager_given_figure(num, fig)
  File "/usr/lib/python3/dist-packages/matplotlib/backends/backend_tkagg.py", line 1049, in new_figure_manager_given_figure
    window = Tk.Tk(className="matplotlib")
  File "/usr/lib/python3.6/tkinter/__init__.py", line 2023, in __init__
    self.tk = _tkinter.create(screenName, baseName, className, interactive, wantobjects, useTk, sync, use)
_tkinter.TclError: couldn't connect to display "localhost:10.0"
proteomes R1@10
Traceback (most recent call last):
  File "recall_time.py", line 47, in <module>
    plt.scatter([y for (x,y, z) in group_record if y > lower_bound], [math.log10(10000 / x * 1000) for (x,y, z) in group_record if y > lower_bound], marker='x', label=f'FLINNG' )
  File "/usr/lib/python3/dist-packages/matplotlib/pyplot.py", line 3364, in scatter
    ax = gca()
  File "/usr/lib/python3/dist-packages/matplotlib/pyplot.py", line 962, in gca
    return gcf().gca(**kwargs)
  File "/usr/lib/python3/dist-packages/matplotlib/pyplot.py", line 592, in gcf
    return figure()
  File "/usr/lib/python3/dist-packages/matplotlib/pyplot.py", line 539, in figure
    **kwargs)
  File "/usr/lib/python3/dist-packages/matplotlib/backend_bases.py", line 171, in new_figure_manager
    return cls.new_figure_manager_given_figure(num, fig)
  File "/usr/lib/python3/dist-packages/matplotlib/backends/backend_tkagg.py", line 1049, in new_figure_manager_given_figure
    window = Tk.Tk(className="matplotlib")
  File "/usr/lib/python3.6/tkinter/__init__.py", line 2023, in __init__
    self.tk = _tkinter.create(screenName, baseName, className, interactive, wantobjects, useTk, sync, use)
_tkinter.TclError: couldn't connect to display "localhost:10.0"
proteomes R1@100
Traceback (most recent call last):
  File "recall_time.py", line 47, in <module>
    plt.scatter([y for (x,y, z) in group_record if y > lower_bound], [math.log10(10000 / x * 1000) for (x,y, z) in group_record if y > lower_bound], marker='x', label=f'FLINNG' )
  File "/usr/lib/python3/dist-packages/matplotlib/pyplot.py", line 3364, in scatter
    ax = gca()
  File "/usr/lib/python3/dist-packages/matplotlib/pyplot.py", line 962, in gca
    return gcf().gca(**kwargs)
  File "/usr/lib/python3/dist-packages/matplotlib/pyplot.py", line 592, in gcf
    return figure()
  File "/usr/lib/python3/dist-packages/matplotlib/pyplot.py", line 539, in figure
    **kwargs)
  File "/usr/lib/python3/dist-packages/matplotlib/backend_bases.py", line 171, in new_figure_manager
    return cls.new_figure_manager_given_figure(num, fig)
  File "/usr/lib/python3/dist-packages/matplotlib/backends/backend_tkagg.py", line 1049, in new_figure_manager_given_figure
    window = Tk.Tk(className="matplotlib")
  File "/usr/lib/python3.6/tkinter/__init__.py", line 2023, in __init__
    self.tk = _tkinter.create(screenName, baseName, className, interactive, wantobjects, useTk, sync, use)
_tkinter.TclError: couldn't connect to display "localhost:10.0"
proteomes R10@10
Traceback (most recent call last):
  File "recall_time.py", line 47, in <module>
    plt.scatter([y for (x,y, z) in group_record if y > lower_bound], [math.log10(10000 / x * 1000) for (x,y, z) in group_record if y > lower_bound], marker='x', label=f'FLINNG' )
  File "/usr/lib/python3/dist-packages/matplotlib/pyplot.py", line 3364, in scatter
    ax = gca()
  File "/usr/lib/python3/dist-packages/matplotlib/pyplot.py", line 962, in gca
    return gcf().gca(**kwargs)
  File "/usr/lib/python3/dist-packages/matplotlib/pyplot.py", line 592, in gcf
    return figure()
  File "/usr/lib/python3/dist-packages/matplotlib/pyplot.py", line 539, in figure
    **kwargs)
  File "/usr/lib/python3/dist-packages/matplotlib/backend_bases.py", line 171, in new_figure_manager
    return cls.new_figure_manager_given_figure(num, fig)
  File "/usr/lib/python3/dist-packages/matplotlib/backends/backend_tkagg.py", line 1049, in new_figure_manager_given_figure
    window = Tk.Tk(className="matplotlib")
  File "/usr/lib/python3.6/tkinter/__init__.py", line 2023, in __init__
    self.tk = _tkinter.create(screenName, baseName, className, interactive, wantobjects, useTk, sync, use)
_tkinter.TclError: couldn't connect to display "localhost:10.0"
proteomes R10@100
Traceback (most recent call last):
  File "recall_time.py", line 47, in <module>
    plt.scatter([y for (x,y, z) in group_record if y > lower_bound], [math.log10(10000 / x * 1000) for (x,y, z) in group_record if y > lower_bound], marker='x', label=f'FLINNG' )
  File "/usr/lib/python3/dist-packages/matplotlib/pyplot.py", line 3364, in scatter
    ax = gca()
  File "/usr/lib/python3/dist-packages/matplotlib/pyplot.py", line 962, in gca
    return gcf().gca(**kwargs)
  File "/usr/lib/python3/dist-packages/matplotlib/pyplot.py", line 592, in gcf
    return figure()
  File "/usr/lib/python3/dist-packages/matplotlib/pyplot.py", line 539, in figure
    **kwargs)
  File "/usr/lib/python3/dist-packages/matplotlib/backend_bases.py", line 171, in new_figure_manager
    return cls.new_figure_manager_given_figure(num, fig)
  File "/usr/lib/python3/dist-packages/matplotlib/backends/backend_tkagg.py", line 1049, in new_figure_manager_given_figure
    window = Tk.Tk(className="matplotlib")
  File "/usr/lib/python3.6/tkinter/__init__.py", line 2023, in __init__
    self.tk = _tkinter.create(screenName, baseName, className, interactive, wantobjects, useTk, sync, use)
_tkinter.TclError: couldn't connect to display "localhost:10.0"
promethion 2 1
Traceback (most recent call last):
  File "recall_precision.py", line 101, in <module>
    plt.scatter(group_record.values(), group_record.keys(), marker='x', label=f'FLINNG' )
  File "/usr/lib/python3/dist-packages/matplotlib/pyplot.py", line 3364, in scatter
    ax = gca()
  File "/usr/lib/python3/dist-packages/matplotlib/pyplot.py", line 962, in gca
    return gcf().gca(**kwargs)
  File "/usr/lib/python3/dist-packages/matplotlib/pyplot.py", line 592, in gcf
    return figure()
  File "/usr/lib/python3/dist-packages/matplotlib/pyplot.py", line 539, in figure
    **kwargs)
  File "/usr/lib/python3/dist-packages/matplotlib/backend_bases.py", line 171, in new_figure_manager
    return cls.new_figure_manager_given_figure(num, fig)
  File "/usr/lib/python3/dist-packages/matplotlib/backends/backend_tkagg.py", line 1049, in new_figure_manager_given_figure
    window = Tk.Tk(className="matplotlib")
  File "/usr/lib/python3.6/tkinter/__init__.py", line 2023, in __init__
    self.tk = _tkinter.create(screenName, baseName, className, interactive, wantobjects, useTk, sync, use)
_tkinter.TclError: couldn't connect to display "localhost:10.0"
promethion 2 10
Traceback (most recent call last):
  File "recall_precision.py", line 101, in <module>
    plt.scatter(group_record.values(), group_record.keys(), marker='x', label=f'FLINNG' )
  File "/usr/lib/python3/dist-packages/matplotlib/pyplot.py", line 3364, in scatter
    ax = gca()
  File "/usr/lib/python3/dist-packages/matplotlib/pyplot.py", line 962, in gca
    return gcf().gca(**kwargs)
  File "/usr/lib/python3/dist-packages/matplotlib/pyplot.py", line 592, in gcf
    return figure()
  File "/usr/lib/python3/dist-packages/matplotlib/pyplot.py", line 539, in figure
    **kwargs)
  File "/usr/lib/python3/dist-packages/matplotlib/backend_bases.py", line 171, in new_figure_manager
    return cls.new_figure_manager_given_figure(num, fig)
  File "/usr/lib/python3/dist-packages/matplotlib/backends/backend_tkagg.py", line 1049, in new_figure_manager_given_figure
    window = Tk.Tk(className="matplotlib")
  File "/usr/lib/python3.6/tkinter/__init__.py", line 2023, in __init__
    self.tk = _tkinter.create(screenName, baseName, className, interactive, wantobjects, useTk, sync, use)
_tkinter.TclError: couldn't connect to display "localhost:10.0"
promethion 20 1
Traceback (most recent call last):
  File "recall_precision.py", line 101, in <module>
    plt.scatter(group_record.values(), group_record.keys(), marker='x', label=f'FLINNG' )
  File "/usr/lib/python3/dist-packages/matplotlib/pyplot.py", line 3364, in scatter
    ax = gca()
  File "/usr/lib/python3/dist-packages/matplotlib/pyplot.py", line 962, in gca
    return gcf().gca(**kwargs)
  File "/usr/lib/python3/dist-packages/matplotlib/pyplot.py", line 592, in gcf
    return figure()
  File "/usr/lib/python3/dist-packages/matplotlib/pyplot.py", line 539, in figure
    **kwargs)
  File "/usr/lib/python3/dist-packages/matplotlib/backend_bases.py", line 171, in new_figure_manager
    return cls.new_figure_manager_given_figure(num, fig)
  File "/usr/lib/python3/dist-packages/matplotlib/backends/backend_tkagg.py", line 1049, in new_figure_manager_given_figure
    window = Tk.Tk(className="matplotlib")
  File "/usr/lib/python3.6/tkinter/__init__.py", line 2023, in __init__
    self.tk = _tkinter.create(screenName, baseName, className, interactive, wantobjects, useTk, sync, use)
_tkinter.TclError: couldn't connect to display "localhost:10.0"
promethion 20 10
Traceback (most recent call last):
  File "recall_precision.py", line 101, in <module>
    plt.scatter(group_record.values(), group_record.keys(), marker='x', label=f'FLINNG' )
  File "/usr/lib/python3/dist-packages/matplotlib/pyplot.py", line 3364, in scatter
    ax = gca()
  File "/usr/lib/python3/dist-packages/matplotlib/pyplot.py", line 962, in gca
    return gcf().gca(**kwargs)
  File "/usr/lib/python3/dist-packages/matplotlib/pyplot.py", line 592, in gcf
    return figure()
  File "/usr/lib/python3/dist-packages/matplotlib/pyplot.py", line 539, in figure
    **kwargs)
  File "/usr/lib/python3/dist-packages/matplotlib/backend_bases.py", line 171, in new_figure_manager
    return cls.new_figure_manager_given_figure(num, fig)
  File "/usr/lib/python3/dist-packages/matplotlib/backends/backend_tkagg.py", line 1049, in new_figure_manager_given_figure
    window = Tk.Tk(className="matplotlib")
  File "/usr/lib/python3.6/tkinter/__init__.py", line 2023, in __init__
    self.tk = _tkinter.create(screenName, baseName, className, interactive, wantobjects, useTk, sync, use)
_tkinter.TclError: couldn't connect to display "localhost:10.0"
promethion 200 1
Traceback (most recent call last):
  File "recall_precision.py", line 101, in <module>
    plt.scatter(group_record.values(), group_record.keys(), marker='x', label=f'FLINNG' )
  File "/usr/lib/python3/dist-packages/matplotlib/pyplot.py", line 3364, in scatter
    ax = gca()
  File "/usr/lib/python3/dist-packages/matplotlib/pyplot.py", line 962, in gca
    return gcf().gca(**kwargs)
  File "/usr/lib/python3/dist-packages/matplotlib/pyplot.py", line 592, in gcf
    return figure()
  File "/usr/lib/python3/dist-packages/matplotlib/pyplot.py", line 539, in figure
    **kwargs)
  File "/usr/lib/python3/dist-packages/matplotlib/backend_bases.py", line 171, in new_figure_manager
    return cls.new_figure_manager_given_figure(num, fig)
  File "/usr/lib/python3/dist-packages/matplotlib/backends/backend_tkagg.py", line 1049, in new_figure_manager_given_figure
    window = Tk.Tk(className="matplotlib")
  File "/usr/lib/python3.6/tkinter/__init__.py", line 2023, in __init__
    self.tk = _tkinter.create(screenName, baseName, className, interactive, wantobjects, useTk, sync, use)
_tkinter.TclError: couldn't connect to display "localhost:10.0"
promethion 200 10
Traceback (most recent call last):
  File "recall_precision.py", line 101, in <module>
    plt.scatter(group_record.values(), group_record.keys(), marker='x', label=f'FLINNG' )
  File "/usr/lib/python3/dist-packages/matplotlib/pyplot.py", line 3364, in scatter
    ax = gca()
  File "/usr/lib/python3/dist-packages/matplotlib/pyplot.py", line 962, in gca
    return gcf().gca(**kwargs)
  File "/usr/lib/python3/dist-packages/matplotlib/pyplot.py", line 592, in gcf
    return figure()
  File "/usr/lib/python3/dist-packages/matplotlib/pyplot.py", line 539, in figure
    **kwargs)
  File "/usr/lib/python3/dist-packages/matplotlib/backend_bases.py", line 171, in new_figure_manager
    return cls.new_figure_manager_given_figure(num, fig)
  File "/usr/lib/python3/dist-packages/matplotlib/backends/backend_tkagg.py", line 1049, in new_figure_manager_given_figure
    window = Tk.Tk(className="matplotlib")
  File "/usr/lib/python3.6/tkinter/__init__.py", line 2023, in __init__
    self.tk = _tkinter.create(screenName, baseName, className, interactive, wantobjects, useTk, sync, use)
_tkinter.TclError: couldn't connect to display "localhost:10.0"
promethion R1@1
Traceback (most recent call last):
  File "recall_time.py", line 47, in <module>
    plt.scatter([y for (x,y, z) in group_record if y > lower_bound], [math.log10(10000 / x * 1000) for (x,y, z) in group_record if y > lower_bound], marker='x', label=f'FLINNG' )
  File "/usr/lib/python3/dist-packages/matplotlib/pyplot.py", line 3364, in scatter
    ax = gca()
  File "/usr/lib/python3/dist-packages/matplotlib/pyplot.py", line 962, in gca
    return gcf().gca(**kwargs)
  File "/usr/lib/python3/dist-packages/matplotlib/pyplot.py", line 592, in gcf
    return figure()
  File "/usr/lib/python3/dist-packages/matplotlib/pyplot.py", line 539, in figure
    **kwargs)
  File "/usr/lib/python3/dist-packages/matplotlib/backend_bases.py", line 171, in new_figure_manager
    return cls.new_figure_manager_given_figure(num, fig)
  File "/usr/lib/python3/dist-packages/matplotlib/backends/backend_tkagg.py", line 1049, in new_figure_manager_given_figure
    window = Tk.Tk(className="matplotlib")
  File "/usr/lib/python3.6/tkinter/__init__.py", line 2023, in __init__
    self.tk = _tkinter.create(screenName, baseName, className, interactive, wantobjects, useTk, sync, use)
_tkinter.TclError: couldn't connect to display "localhost:10.0"
promethion R1@10
Traceback (most recent call last):
  File "recall_time.py", line 47, in <module>
    plt.scatter([y for (x,y, z) in group_record if y > lower_bound], [math.log10(10000 / x * 1000) for (x,y, z) in group_record if y > lower_bound], marker='x', label=f'FLINNG' )
  File "/usr/lib/python3/dist-packages/matplotlib/pyplot.py", line 3364, in scatter
    ax = gca()
  File "/usr/lib/python3/dist-packages/matplotlib/pyplot.py", line 962, in gca
    return gcf().gca(**kwargs)
  File "/usr/lib/python3/dist-packages/matplotlib/pyplot.py", line 592, in gcf
    return figure()
  File "/usr/lib/python3/dist-packages/matplotlib/pyplot.py", line 539, in figure
    **kwargs)
  File "/usr/lib/python3/dist-packages/matplotlib/backend_bases.py", line 171, in new_figure_manager
    return cls.new_figure_manager_given_figure(num, fig)
  File "/usr/lib/python3/dist-packages/matplotlib/backends/backend_tkagg.py", line 1049, in new_figure_manager_given_figure
    window = Tk.Tk(className="matplotlib")
  File "/usr/lib/python3.6/tkinter/__init__.py", line 2023, in __init__
    self.tk = _tkinter.create(screenName, baseName, className, interactive, wantobjects, useTk, sync, use)
_tkinter.TclError: couldn't connect to display "localhost:10.0"
promethion R1@100
Traceback (most recent call last):
  File "recall_time.py", line 47, in <module>
    plt.scatter([y for (x,y, z) in group_record if y > lower_bound], [math.log10(10000 / x * 1000) for (x,y, z) in group_record if y > lower_bound], marker='x', label=f'FLINNG' )
  File "/usr/lib/python3/dist-packages/matplotlib/pyplot.py", line 3364, in scatter
    ax = gca()
  File "/usr/lib/python3/dist-packages/matplotlib/pyplot.py", line 962, in gca
    return gcf().gca(**kwargs)
  File "/usr/lib/python3/dist-packages/matplotlib/pyplot.py", line 592, in gcf
    return figure()
  File "/usr/lib/python3/dist-packages/matplotlib/pyplot.py", line 539, in figure
    **kwargs)
  File "/usr/lib/python3/dist-packages/matplotlib/backend_bases.py", line 171, in new_figure_manager
    return cls.new_figure_manager_given_figure(num, fig)
  File "/usr/lib/python3/dist-packages/matplotlib/backends/backend_tkagg.py", line 1049, in new_figure_manager_given_figure
    window = Tk.Tk(className="matplotlib")
  File "/usr/lib/python3.6/tkinter/__init__.py", line 2023, in __init__
    self.tk = _tkinter.create(screenName, baseName, className, interactive, wantobjects, useTk, sync, use)
_tkinter.TclError: couldn't connect to display "localhost:10.0"
promethion R10@10
Traceback (most recent call last):
  File "recall_time.py", line 47, in <module>
    plt.scatter([y for (x,y, z) in group_record if y > lower_bound], [math.log10(10000 / x * 1000) for (x,y, z) in group_record if y > lower_bound], marker='x', label=f'FLINNG' )
  File "/usr/lib/python3/dist-packages/matplotlib/pyplot.py", line 3364, in scatter
    ax = gca()
  File "/usr/lib/python3/dist-packages/matplotlib/pyplot.py", line 962, in gca
    return gcf().gca(**kwargs)
  File "/usr/lib/python3/dist-packages/matplotlib/pyplot.py", line 592, in gcf
    return figure()
  File "/usr/lib/python3/dist-packages/matplotlib/pyplot.py", line 539, in figure
    **kwargs)
  File "/usr/lib/python3/dist-packages/matplotlib/backend_bases.py", line 171, in new_figure_manager
    return cls.new_figure_manager_given_figure(num, fig)
  File "/usr/lib/python3/dist-packages/matplotlib/backends/backend_tkagg.py", line 1049, in new_figure_manager_given_figure
    window = Tk.Tk(className="matplotlib")
  File "/usr/lib/python3.6/tkinter/__init__.py", line 2023, in __init__
    self.tk = _tkinter.create(screenName, baseName, className, interactive, wantobjects, useTk, sync, use)
_tkinter.TclError: couldn't connect to display "localhost:10.0"
promethion R10@100
Traceback (most recent call last):
  File "recall_time.py", line 47, in <module>
    plt.scatter([y for (x,y, z) in group_record if y > lower_bound], [math.log10(10000 / x * 1000) for (x,y, z) in group_record if y > lower_bound], marker='x', label=f'FLINNG' )
  File "/usr/lib/python3/dist-packages/matplotlib/pyplot.py", line 3364, in scatter
    ax = gca()
  File "/usr/lib/python3/dist-packages/matplotlib/pyplot.py", line 962, in gca
    return gcf().gca(**kwargs)
  File "/usr/lib/python3/dist-packages/matplotlib/pyplot.py", line 592, in gcf
    return figure()
  File "/usr/lib/python3/dist-packages/matplotlib/pyplot.py", line 539, in figure
    **kwargs)
  File "/usr/lib/python3/dist-packages/matplotlib/backend_bases.py", line 171, in new_figure_manager
    return cls.new_figure_manager_given_figure(num, fig)
  File "/usr/lib/python3/dist-packages/matplotlib/backends/backend_tkagg.py", line 1049, in new_figure_manager_given_figure
    window = Tk.Tk(className="matplotlib")
  File "/usr/lib/python3.6/tkinter/__init__.py", line 2023, in __init__
    self.tk = _tkinter.create(screenName, baseName, className, interactive, wantobjects, useTk, sync, use)
_tkinter.TclError: couldn't connect to display "localhost:10.0"
promethion R1@1
Traceback (most recent call last):
  File "recall_time.py", line 47, in <module>
    plt.scatter([y for (x,y, z) in group_record if y > lower_bound], [math.log10(10000 / x * 1000) for (x,y, z) in group_record if y > lower_bound], marker='x', label=f'FLINNG' )
  File "/usr/lib/python3/dist-packages/matplotlib/pyplot.py", line 3364, in scatter
    ax = gca()
  File "/usr/lib/python3/dist-packages/matplotlib/pyplot.py", line 962, in gca
    return gcf().gca(**kwargs)
  File "/usr/lib/python3/dist-packages/matplotlib/pyplot.py", line 592, in gcf
    return figure()
  File "/usr/lib/python3/dist-packages/matplotlib/pyplot.py", line 539, in figure
    **kwargs)
  File "/usr/lib/python3/dist-packages/matplotlib/backend_bases.py", line 171, in new_figure_manager
    return cls.new_figure_manager_given_figure(num, fig)
  File "/usr/lib/python3/dist-packages/matplotlib/backends/backend_tkagg.py", line 1049, in new_figure_manager_given_figure
    window = Tk.Tk(className="matplotlib")
  File "/usr/lib/python3.6/tkinter/__init__.py", line 2023, in __init__
    self.tk = _tkinter.create(screenName, baseName, className, interactive, wantobjects, useTk, sync, use)
_tkinter.TclError: couldn't connect to display "localhost:10.0"
promethion R1@10
Traceback (most recent call last):
  File "recall_time.py", line 47, in <module>
    plt.scatter([y for (x,y, z) in group_record if y > lower_bound], [math.log10(10000 / x * 1000) for (x,y, z) in group_record if y > lower_bound], marker='x', label=f'FLINNG' )
  File "/usr/lib/python3/dist-packages/matplotlib/pyplot.py", line 3364, in scatter
    ax = gca()
  File "/usr/lib/python3/dist-packages/matplotlib/pyplot.py", line 962, in gca
    return gcf().gca(**kwargs)
  File "/usr/lib/python3/dist-packages/matplotlib/pyplot.py", line 592, in gcf
    return figure()
  File "/usr/lib/python3/dist-packages/matplotlib/pyplot.py", line 539, in figure
    **kwargs)
  File "/usr/lib/python3/dist-packages/matplotlib/backend_bases.py", line 171, in new_figure_manager
    return cls.new_figure_manager_given_figure(num, fig)
  File "/usr/lib/python3/dist-packages/matplotlib/backends/backend_tkagg.py", line 1049, in new_figure_manager_given_figure
    window = Tk.Tk(className="matplotlib")
  File "/usr/lib/python3.6/tkinter/__init__.py", line 2023, in __init__
    self.tk = _tkinter.create(screenName, baseName, className, interactive, wantobjects, useTk, sync, use)
_tkinter.TclError: couldn't connect to display "localhost:10.0"
promethion R1@100
Traceback (most recent call last):
  File "recall_time.py", line 47, in <module>
    plt.scatter([y for (x,y, z) in group_record if y > lower_bound], [math.log10(10000 / x * 1000) for (x,y, z) in group_record if y > lower_bound], marker='x', label=f'FLINNG' )
  File "/usr/lib/python3/dist-packages/matplotlib/pyplot.py", line 3364, in scatter
    ax = gca()
  File "/usr/lib/python3/dist-packages/matplotlib/pyplot.py", line 962, in gca
    return gcf().gca(**kwargs)
  File "/usr/lib/python3/dist-packages/matplotlib/pyplot.py", line 592, in gcf
    return figure()
  File "/usr/lib/python3/dist-packages/matplotlib/pyplot.py", line 539, in figure
    **kwargs)
  File "/usr/lib/python3/dist-packages/matplotlib/backend_bases.py", line 171, in new_figure_manager
    return cls.new_figure_manager_given_figure(num, fig)
  File "/usr/lib/python3/dist-packages/matplotlib/backends/backend_tkagg.py", line 1049, in new_figure_manager_given_figure
    window = Tk.Tk(className="matplotlib")
  File "/usr/lib/python3.6/tkinter/__init__.py", line 2023, in __init__
    self.tk = _tkinter.create(screenName, baseName, className, interactive, wantobjects, useTk, sync, use)
_tkinter.TclError: couldn't connect to display "localhost:10.0"
promethion R10@10
Traceback (most recent call last):
  File "recall_time.py", line 47, in <module>
    plt.scatter([y for (x,y, z) in group_record if y > lower_bound], [math.log10(10000 / x * 1000) for (x,y, z) in group_record if y > lower_bound], marker='x', label=f'FLINNG' )
  File "/usr/lib/python3/dist-packages/matplotlib/pyplot.py", line 3364, in scatter
    ax = gca()
  File "/usr/lib/python3/dist-packages/matplotlib/pyplot.py", line 962, in gca
    return gcf().gca(**kwargs)
  File "/usr/lib/python3/dist-packages/matplotlib/pyplot.py", line 592, in gcf
    return figure()
  File "/usr/lib/python3/dist-packages/matplotlib/pyplot.py", line 539, in figure
    **kwargs)
  File "/usr/lib/python3/dist-packages/matplotlib/backend_bases.py", line 171, in new_figure_manager
    return cls.new_figure_manager_given_figure(num, fig)
  File "/usr/lib/python3/dist-packages/matplotlib/backends/backend_tkagg.py", line 1049, in new_figure_manager_given_figure
    window = Tk.Tk(className="matplotlib")
  File "/usr/lib/python3.6/tkinter/__init__.py", line 2023, in __init__
    self.tk = _tkinter.create(screenName, baseName, className, interactive, wantobjects, useTk, sync, use)
_tkinter.TclError: couldn't connect to display "localhost:10.0"
promethion R10@100
Traceback (most recent call last):
  File "recall_time.py", line 47, in <module>
    plt.scatter([y for (x,y, z) in group_record if y > lower_bound], [math.log10(10000 / x * 1000) for (x,y, z) in group_record if y > lower_bound], marker='x', label=f'FLINNG' )
  File "/usr/lib/python3/dist-packages/matplotlib/pyplot.py", line 3364, in scatter
    ax = gca()
  File "/usr/lib/python3/dist-packages/matplotlib/pyplot.py", line 962, in gca
    return gcf().gca(**kwargs)
  File "/usr/lib/python3/dist-packages/matplotlib/pyplot.py", line 592, in gcf
    return figure()
  File "/usr/lib/python3/dist-packages/matplotlib/pyplot.py", line 539, in figure
    **kwargs)
  File "/usr/lib/python3/dist-packages/matplotlib/backend_bases.py", line 171, in new_figure_manager
    return cls.new_figure_manager_given_figure(num, fig)
  File "/usr/lib/python3/dist-packages/matplotlib/backends/backend_tkagg.py", line 1049, in new_figure_manager_given_figure
    window = Tk.Tk(className="matplotlib")
  File "/usr/lib/python3.6/tkinter/__init__.py", line 2023, in __init__
    self.tk = _tkinter.create(screenName, baseName, className, interactive, wantobjects, useTk, sync, use)
_tkinter.TclError: couldn't connect to display "localhost:10.0"
